Workbook

Sheet Data Alokasi Mitra per Bulan
A1: Helper | B1: Helper2 | C1: Nama | D1: Bulan | E1: Kegiatan | F1: PML | G1: Honor | H1: Honor Per Satuan | I1: Satuan | J1: Volume | K1: Mata Anggaran | L1: Tanggal Mulai | M1: Tanggal Berakhir | N1: Lebih Bayar | R1: Alamat | S1: Pekerjaan | Y1: =EOMONTH(TODAY(),-2)+1 -> 45992 | Z1: =Y1 -> 45992 | BE1: =EOMONTH(Y1,0)+1 -> 46023 | BF1: =BE1 -> 46023 | CK1: =EOMONTH(BE1,0)+1 -> 46054 | CL1: =CK1 -> 46054 | DQ1: =EOMONTH(CK1,0)+1 -> 46082 | EW1: =EOMONTH(DQ1,0)+1 -> 46113 | GC1: =EOMONTH(EW1,0)+1 -> 46143 | HI1: =EOMONTH(GC1,0)+1 -> 46174 | IO1: =EOMONTH(HI1,0)+1 -> 46204 | JU1: =EOMONTH(IO1,0)+1 -> 46235 | LA1: =EOMONTH(JU1,0)+1 -> 46266 | MG1: =EOMONTH(LA1,0)+1 -> 46296 | NM1: =EOMONTH(MG1,0)+1 -> 46327
A2: =U2&"-"&COUNTIF(U$2:U2,U2) -> GaberielJanuari-1 | B2: =CONCATENATE(F2,D2,E2) -> JanuariCONTOH | C2: Gaberiel | D2: Januari | E2: CONTOH | G2: 660000 | H2: 55000 | N2: =_xludf.IFNA(IF(X2>3530000,3530000-X2,""),"") -> #NAME? | R2: {=VLOOKUP(C2,DB!A:D,2,FALSE)} -> #N/A | S2: {=VLOOKUP(C2,DB!A:D,3,FALSE)} -> #N/A | T2: CARA MEMILIH TANGGAL DENGAN KLIK 2 KALI PADA CELL | U2: =CONCATENATE(C2,D2) -> GaberielJanuari | V2: =IF(M2="",_xludf.SWITCH(D2,"Januari",EOMONTH("01/01/2024",0),"Februari",EOMONTH("01/01/2024",1),"Maret",EOMONTH("01/01/2024",2),"April",EOMONTH("01/01/2024",3),"Mei",EOMONTH("01/01/2024",4),"Juni",EOMONTH("01/01/2024",5),"Juli",EOMONTH("01/01/2024",6),"Agustus",EOMONTH("01/01/2024",7),"September",EOMONTH("01/01/2024",8),"Oktober",EOMONTH("01/01/2024",9),"November",EOMONTH("01/01/2024",10),"Desember",EOMONTH("01/01/2024",11)),M2) -> #NAME? | X2: =VLOOKUP(CONCATENATE(C2,D2),'Honor 2025'!A:D,4,FALSE) -> #N/A
A3: =U3&"-"&COUNTIF(U$2:U3,U3) -> ARTHUR CARLOS BOGARJanuari-1 | B3: =CONCATENATE(F3,D3,E3) -> Farhan, S.Tr.Stat.JanuariPES | C3: ARTHUR CARLOS BOGAR | D3: Januari | E3: PES | F3: Farhan, S.Tr.Stat. | G3: 954000 | H3: 53000 | I3: Dok | J3: 18 | K3: 2908.BMA.004.005.A.521213 | L3: 45659 | M3: 45688 | N3: =_xludf.IFNA(IF(X3>3530000,3530000-X3,""),"") -> #NAME? | R3: {=VLOOKUP(C3,DB!A:D,2,FALSE)} -> KELURAHAN ISLAM LINGKUNGAN 3 | S3: {=VLOOKUP(C3,DB!A:D,3,FALSE)} -> Arthur.bogar@yahoo.com | T3: CARA MEMILIH TANGGAL DENGAN KLIK 2 KALI PADA CELL | U3: =CONCATENATE(C3,D3) -> ARTHUR CARLOS BOGARJanuari | V3: =IF(M3="",_xludf.SWITCH(D3,"Januari",EOMONTH("01/01/2024",0),"Februari",EOMONTH("01/01/2024",1),"Maret",EOMONTH("01/01/2024",2),"April",EOMONTH("01/01/2024",3),"Mei",EOMONTH("01/01/2024",4),"Juni",EOMONTH("01/01/2024",5),"Juli",EOMONTH("01/01/2024",6),"Agustus",EOMONTH("01/01/2024",7),"September",EOMONTH("01/01/2024",8),"Oktober",EOMONTH("01/01/2024",9),"November",EOMONTH("01/01/2024",10),"Desember",EOMONTH("01/01/2024",11)),M3) -> 45688 | X3: =VLOOKUP(CONCATENATE(C3,D3),'Honor 2025'!A:D,4,FALSE) -> 954000
A4: =U4&"-"&COUNTIF(U$2:U4,U4) -> Cecillia ArthoJanuari-1 | B4: =CONCATENATE(F4,D4,E4) -> Farhan, S.Tr.Stat.JanuariPES | C4: Cecillia Artho | D4: Januari | E4: PES | F4: Farhan, S.Tr.Stat. | G4: 954000 | H4: 53000 | I4: Dok | J4: 18 | K4: 2908.BMA.004.005.A.521213 | L4: 45659 | M4: 45688 | N4: =_xludf.IFNA(IF(X4>3530000,3530000-X4,""),"") -> #NAME? | R4: {=VLOOKUP(C4,DB!A:D,2,FALSE)} -> Jl. Sam Ratulangi 18 no 34, Lingkungan IV | S4: {=VLOOKUP(C4,DB!A:D,3,FALSE)} -> ryuuseiishida@gmail.com | T4: CARA MEMILIH TANGGAL DENGAN KLIK 2 KALI PADA CELL | U4: =CONCATENATE(C4,D4) -> Cecillia ArthoJanuari | V4: =IF(M4="",_xludf.SWITCH(D4,"Januari",EOMONTH("01/01/2024",0),"Februari",EOMONTH("01/01/2024",1),"Maret",EOMONTH("01/01/2024",2),"April",EOMONTH("01/01/2024",3),"Mei",EOMONTH("01/01/2024",4),"Juni",EOMONTH("01/01/2024",5),"Juli",EOMONTH("01/01/2024",6),"Agustus",EOMONTH("01/01/2024",7),"September",EOMONTH("01/01/2024",8),"Oktober",EOMONTH("01/01/2024",9),"November",EOMONTH("01/01/2024",10),"Desember",EOMONTH("01/01/2024",11)),M4) -> 45688 | X4: =VLOOKUP(CONCATENATE(C4,D4),'Honor 2025'!A:D,4,FALSE) -> 1614000
A5: =U5&"-"&COUNTIF(U$2:U5,U5) -> Steven Sorts Paulus AkayJanuari-1 | B5: =CONCATENATE(F5,D5,E5) -> Farhan, S.Tr.Stat.JanuariPES | C5: Steven Sorts Paulus Akay | D5: Januari | E5: PES | F5: Farhan, S.Tr.Stat. | G5: 3498000 | H5: 53000 | I5: Dok | J5: 66 | K5: 2908.BMA.004.005.A.521213 | L5: 45659 | M5: 45688 | N5: =_xludf.IFNA(IF(X5>3530000,3530000-X5,""),"") -> #NAME? | R5: {=VLOOKUP(C5,DB!A:D,2,FALSE)} -> PERUM GPI Jalan Delima 3 nomor 15 | S5: {=VLOOKUP(C5,DB!A:D,3,FALSE)} -> epenakay@gmail.com | T5: CARA MEMILIH TANGGAL DENGAN KLIK 2 KALI PADA CELL | U5: =CONCATENATE(C5,D5) -> Steven Sorts Paulus AkayJanuari | V5: =IF(M5="",_xludf.SWITCH(D5,"Januari",EOMONTH("01/01/2024",0),"Februari",EOMONTH("01/01/2024",1),"Maret",EOMONTH("01/01/2024",2),"April",EOMONTH("01/01/2024",3),"Mei",EOMONTH("01/01/2024",4),"Juni",EOMONTH("01/01/2024",5),"Juli",EOMONTH("01/01/2024",6),"Agustus",EOMONTH("01/01/2024",7),"September",EOMONTH("01/01/2024",8),"Oktober",EOMONTH("01/01/2024",9),"November",EOMONTH("01/01/2024",10),"Desember",EOMONTH("01/01/2024",11)),M5) -> 45688 | X5: =VLOOKUP(CONCATENATE(C5,D5),'Honor 2025'!A:D,4,FALSE) -> 3498000
A6: =U6&"-"&COUNTIF(U$2:U6,U6) -> Alvani Bregina NgongoloyJanuari-1 | B6: =CONCATENATE(F6,D6,E6) -> Olivia Widyawaty SahambangungJanuariVHTS | C6: Alvani Bregina Ngongoloy | D6: Januari | E6: VHTS | F6: Olivia Widyawaty Sahambangung | G6: 660000 | H6: 66000 | I6: Dok | J6: 10 | K6: 2908.BMA.004.005.A.521213 | L6: 45659 | M6: 45677 | N6: =_xludf.IFNA(IF(X6>3530000,3530000-X6,""),"") -> #NAME? | R6: {=VLOOKUP(C6,DB!A:D,2,FALSE)} -> Kelurahan Ranotana Weru Lingkunan 3 | S6: {=VLOOKUP(C6,DB!A:D,3,FALSE)} -> Figliogina05@gmail.com | T6: CARA MEMILIH TANGGAL DENGAN KLIK 2 KALI PADA CELL | U6: =CONCATENATE(C6,D6) -> Alvani Bregina NgongoloyJanuari | V6: =IF(M6="",_xludf.SWITCH(D6,"Januari",EOMONTH("01/01/2024",0),"Februari",EOMONTH("01/01/2024",1),"Maret",EOMONTH("01/01/2024",2),"April",EOMONTH("01/01/2024",3),"Mei",EOMONTH("01/01/2024",4),"Juni",EOMONTH("01/01/2024",5),"Juli",EOMONTH("01/01/2024",6),"Agustus",EOMONTH("01/01/2024",7),"September",EOMONTH("01/01/2024",8),"Oktober",EOMONTH("01/01/2024",9),"November",EOMONTH("01/01/2024",10),"Desember",EOMONTH("01/01/2024",11)),M6) -> 45677 | X6: =VLOOKUP(CONCATENATE(C6,D6),'Honor 2025'!A:D,4,FALSE) -> 1458000
A7: =U7&"-"&COUNTIF(U$2:U7,U7) -> Cecillia ArthoJanuari-2 | B7: =CONCATENATE(F7,D7,E7) -> Rahadita Nur Haida, S.Tr.Stat.JanuariVHTS | C7: Cecillia Artho | D7: Januari | E7: VHTS | F7: Rahadita Nur Haida, S.Tr.Stat. | G7: 660000 | H7: 66000 | I7: Dok | J7: 10 | K7: 2908.BMA.004.005.A.521213 | L7: 45659 | M7: 45677 | N7: =_xludf.IFNA(IF(X7>3530000,3530000-X7,""),"") -> #NAME? | R7: {=VLOOKUP(C7,DB!A:D,2,FALSE)} -> Jl. Sam Ratulangi 18 no 34, Lingkungan IV | S7: {=VLOOKUP(C7,DB!A:D,3,FALSE)} -> ryuuseiishida@gmail.com | T7: CARA MEMILIH TANGGAL DENGAN KLIK 2 KALI PADA CELL | U7: =CONCATENATE(C7,D7) -> Cecillia ArthoJanuari | V7: =IF(M7="",_xludf.SWITCH(D7,"Januari",EOMONTH("01/01/2024",0),"Februari",EOMONTH("01/01/2024",1),"Maret",EOMONTH("01/01/2024",2),"April",EOMONTH("01/01/2024",3),"Mei",EOMONTH("01/01/2024",4),"Juni",EOMONTH("01/01/2024",5),"Juli",EOMONTH("01/01/2024",6),"Agustus",EOMONTH("01/01/2024",7),"September",EOMONTH("01/01/2024",8),"Oktober",EOMONTH("01/01/2024",9),"November",EOMONTH("01/01/2024",10),"Desember",EOMONTH("01/01/2024",11)),M7) -> 45677 | X7: =VLOOKUP(CONCATENATE(C7,D7),'Honor 2025'!A:D,4,FALSE) -> 1614000
A8: =U8&"-"&COUNTIF(U$2:U8,U8) -> Esther Angle SepangJanuari-1 | B8: =CONCATENATE(F8,D8,E8) -> Olivia Widyawaty SahambangungJanuariVHTS | C8: Esther Angle Sepang | D8: Januari | E8: VHTS | F8: Olivia Widyawaty Sahambangung | G8: 660000 | H8: 66000 | I8: Dok | J8: 10 | K8: 2908.BMA.004.005.A.521213 | L8: 45659 | M8: 45677 | N8: =_xludf.IFNA(IF(X8>3530000,3530000-X8,""),"") -> #NAME? | R8: {=VLOOKUP(C8,DB!A:D,2,FALSE)} -> Bumi Nyiur Lingkungan 2 | S8: {=VLOOKUP(C8,DB!A:D,3,FALSE)} -> esthersepang24@gmail.com | T8: CARA MEMILIH TANGGAL DENGAN KLIK 2 KALI PADA CELL | U8: =CONCATENATE(C8,D8) -> Esther Angle SepangJanuari | V8: =IF(M8="",_xludf.SWITCH(D8,"Januari",EOMONTH("01/01/2024",0),"Februari",EOMONTH("01/01/2024",1),"Maret",EOMONTH("01/01/2024",2),"April",EOMONTH("01/01/2024",3),"Mei",EOMONTH("01/01/2024",4),"Juni",EOMONTH("01/01/2024",5),"Juli",EOMONTH("01/01/2024",6),"Agustus",EOMONTH("01/01/2024",7),"September",EOMONTH("01/01/2024",8),"Oktober",EOMONTH("01/01/2024",9),"November",EOMONTH("01/01/2024",10),"Desember",EOMONTH("01/01/2024",11)),M8) -> 45677 | X8: =VLOOKUP(CONCATENATE(C8,D8),'Honor 2025'!A:D,4,FALSE) -> 1254000
A9: =U9&"-"&COUNTIF(U$2:U9,U9) -> MARLIN TELMA OCTAVIA KARIOJanuari-1 | B9: =CONCATENATE(F9,D9,E9) -> Rahadita Nur Haida, S.Tr.Stat.JanuariVHTS | C9: MARLIN TELMA OCTAVIA KARIO | D9: Januari | E9: VHTS | F9: Rahadita Nur Haida, S.Tr.Stat. | G9: 660000 | H9: 66000 | I9: Dok | J9: 10 | K9: 2908.BMA.004.005.A.521213 | L9: 45659 | M9: 45677 | N9: =_xludf.IFNA(IF(X9>3530000,3530000-X9,""),"") -> #NAME? | R9: {=VLOOKUP(C9,DB!A:D,2,FALSE)} -> Jl Sam ratulangi 21 | S9: {=VLOOKUP(C9,DB!A:D,3,FALSE)} -> Kariomarlin@gmail.com | T9: CARA MEMILIH TANGGAL DENGAN KLIK 2 KALI PADA CELL | U9: =CONCATENATE(C9,D9) -> MARLIN TELMA OCTAVIA KARIOJanuari | V9: =IF(M9="",_xludf.SWITCH(D9,"Januari",EOMONTH("01/01/2024",0),"Februari",EOMONTH("01/01/2024",1),"Maret",EOMONTH("01/01/2024",2),"April",EOMONTH("01/01/2024",3),"Mei",EOMONTH("01/01/2024",4),"Juni",EOMONTH("01/01/2024",5),"Juli",EOMONTH("01/01/2024",6),"Agustus",EOMONTH("01/01/2024",7),"September",EOMONTH("01/01/2024",8),"Oktober",EOMONTH("01/01/2024",9),"November",EOMONTH("01/01/2024",10),"Desember",EOMONTH("01/01/2024",11)),M9) -> 45677 | X9: =VLOOKUP(CONCATENATE(C9,D9),'Honor 2025'!A:D,4,FALSE) -> 1108000
A10: =U10&"-"&COUNTIF(U$2:U10,U10) -> Reini Clara PaulusJanuari-1 | B10: =CONCATENATE(F10,D10,E10) -> Rahadita Nur Haida, S.Tr.Stat.JanuariVHTS | C10: Reini Clara Paulus | D10: Januari | E10: VHTS | F10: Rahadita Nur Haida, S.Tr.Stat. | G10: 660000 | H10: 66000 | I10: Dok | J10: 10 | K10: 2908.BMA.004.005.A.521213 | L10: 45659 | M10: 45677 | N10: =_xludf.IFNA(IF(X10>3530000,3530000-X10,""),"") -> #NAME? | R10: {=VLOOKUP(C10,DB!A:D,2,FALSE)} -> Jalan Teluk Tomini No. 170 | S10: {=VLOOKUP(C10,DB!A:D,3,FALSE)} -> reinizalora@gmail.com | T10: CARA MEMILIH TANGGAL DENGAN KLIK 2 KALI PADA CELL | U10: =CONCATENATE(C10,D10) -> Reini Clara PaulusJanuari | V10: =IF(M10="",_xludf.SWITCH(D10,"Januari",EOMONTH("01/01/2024",0),"Februari",EOMONTH("01/01/2024",1),"Maret",EOMONTH("01/01/2024",2),"April",EOMONTH("01/01/2024",3),"Mei",EOMONTH("01/01/2024",4),"Juni",EOMONTH("01/01/2024",5),"Juli",EOMONTH("01/01/2024",6),"Agustus",EOMONTH("01/01/2024",7),"September",EOMONTH("01/01/2024",8),"Oktober",EOMONTH("01/01/2024",9),"November",EOMONTH("01/01/2024",10),"Desember",EOMONTH("01/01/2024",11)),M10) -> 45677 | X10: =VLOOKUP(CONCATENATE(C10,D10),'Honor 2025'!A:D,4,FALSE) -> 3426000
A11: =U11&"-"&COUNTIF(U$2:U11,U11) -> SRI RETNO PUSPITOJanuari-1 | B11: =CONCATENATE(F11,D11,E11) -> Rahadita Nur Haida, S.Tr.Stat.JanuariVHTS | C11: SRI RETNO PUSPITO | D11: Januari | E11: VHTS | F11: Rahadita Nur Haida, S.Tr.Stat. | G11: 660000 | H11: 66000 | I11: Dok | J11: 10 | K11: 2908.BMA.004.005.A.521213 | L11: 45659 | M11: 45677 | N11: =_xludf.IFNA(IF(X11>3530000,3530000-X11,""),"") -> #NAME? | R11: {=VLOOKUP(C11,DB!A:D,2,FALSE)} -> Jln A Yani 15 no 5 manado | S11: {=VLOOKUP(C11,DB!A:D,3,FALSE)} -> sriretnopuspito@gmail.com | T11: CARA MEMILIH TANGGAL DENGAN KLIK 2 KALI PADA CELL | U11: =CONCATENATE(C11,D11) -> SRI RETNO PUSPITOJanuari | V11: =IF(M11="",_xludf.SWITCH(D11,"Januari",EOMONTH("01/01/2024",0),"Februari",EOMONTH("01/01/2024",1),"Maret",EOMONTH("01/01/2024",2),"April",EOMONTH("01/01/2024",3),"Mei",EOMONTH("01/01/2024",4),"Juni",EOMONTH("01/01/2024",5),"Juli",EOMONTH("01/01/2024",6),"Agustus",EOMONTH("01/01/2024",7),"September",EOMONTH("01/01/2024",8),"Oktober",EOMONTH("01/01/2024",9),"November",EOMONTH("01/01/2024",10),"Desember",EOMONTH("01/01/2024",11)),M11) -> 45677 | X11: =VLOOKUP(CONCATENATE(C11,D11),'Honor 2025'!A:D,4,FALSE) -> 660000
A12: =U12&"-"&COUNTIF(U$2:U12,U12) -> Farida TampangJanuari-1 | B12: =CONCATENATE(F12,D12,E12) -> Farhan, S.Tr.Stat.JanuariSurvei STKU | C12: Farida Tampang | D12: Januari | E12: Survei STKU | F12: Farhan, S.Tr.Stat. | G12: 462000 | H12: 66000 | I12: Dok | J12: 7 | K12: 2902.BMA.004.005.A.524113 | L12: 45659 | M12: 45672 | N12: =_xludf.IFNA(IF(X12>3530000,3530000-X12,""),"") -> #NAME? | R12: {=VLOOKUP(C12,DB!A:D,2,FALSE)} -> Perum Malalayang Permai Blok B Lingkungan 5 | S12: {=VLOOKUP(C12,DB!A:D,3,FALSE)} -> frydatampang30730@gmail.com | T12: CARA MEMILIH TANGGAL DENGAN KLIK 2 KALI PADA CELL | U12: =CONCATENATE(C12,D12) -> Farida TampangJanuari | V12: =IF(M12="",_xludf.SWITCH(D12,"Januari",EOMONTH("01/01/2024",0),"Februari",EOMONTH("01/01/2024",1),"Maret",EOMONTH("01/01/2024",2),"April",EOMONTH("01/01/2024",3),"Mei",EOMONTH("01/01/2024",4),"Juni",EOMONTH("01/01/2024",5),"Juli",EOMONTH("01/01/2024",6),"Agustus",EOMONTH("01/01/2024",7),"September",EOMONTH("01/01/2024",8),"Oktober",EOMONTH("01/01/2024",9),"November",EOMONTH("01/01/2024",10),"Desember",EOMONTH("01/01/2024",11)),M12) -> 45672 | X12: =VLOOKUP(CONCATENATE(C12,D12),'Honor 2025'!A:D,4,FALSE) -> 2718000
A13: =U13&"-"&COUNTIF(U$2:U13,U13) -> Reini Clara PaulusJanuari-2 | B13: =CONCATENATE(F13,D13,E13) -> Farhan, S.Tr.Stat.JanuariSurvei STKU | C13: Reini Clara Paulus | D13: Januari | E13: Survei STKU | F13: Farhan, S.Tr.Stat. | G13: 462000 | H13: 66000 | I13: Dok | J13: 7 | K13: 2902.BMA.004.005.A.524113 | L13: 45659 | M13: 45672 | N13: =_xludf.IFNA(IF(X13>3530000,3530000-X13,""),"") -> #NAME? | R13: {=VLOOKUP(C13,DB!A:D,2,FALSE)} -> Jalan Teluk Tomini No. 170 | S13: {=VLOOKUP(C13,DB!A:D,3,FALSE)} -> reinizalora@gmail.com | T13: CARA MEMILIH TANGGAL DENGAN KLIK 2 KALI PADA CELL | U13: =CONCATENATE(C13,D13) -> Reini Clara PaulusJanuari | V13: =IF(M13="",_xludf.SWITCH(D13,"Januari",EOMONTH("01/01/2024",0),"Februari",EOMONTH("01/01/2024",1),"Maret",EOMONTH("01/01/2024",2),"April",EOMONTH("01/01/2024",3),"Mei",EOMONTH("01/01/2024",4),"Juni",EOMONTH("01/01/2024",5),"Juli",EOMONTH("01/01/2024",6),"Agustus",EOMONTH("01/01/2024",7),"September",EOMONTH("01/01/2024",8),"Oktober",EOMONTH("01/01/2024",9),"November",EOMONTH("01/01/2024",10),"Desember",EOMONTH("01/01/2024",11)),M13) -> 45672 | X13: =VLOOKUP(CONCATENATE(C13,D13),'Honor 2025'!A:D,4,FALSE) -> 3426000
A14: =U14&"-"&COUNTIF(U$2:U14,U14) -> Adriana TandajuJanuari-1 | B14: =CONCATENATE(F14,D14,E14) -> Vini Cristin, S.Tr.Stat.JanuariSurvei Harga Konsumen (HK 1.1 Pasar) | C14: Adriana Tandaju | D14: Januari | E14: Survei Harga Konsumen (HK 1.1 Pasar) | F14: Vini Cristin, S.Tr.Stat. | G14: =H14*J14 -> 225000 | H14: 45000 | I14: Dok | J14: 5 | K14: 2903.QMA.006.005.A.521213 | L14: 45663 | M14: 45678 | N14: =_xludf.IFNA(IF(X14>3530000,3530000-X14,""),"") -> #NAME? | R14: {=VLOOKUP(C14,DB!A:D,2,FALSE)} -> JL.PRAMUKA NO.29 | S14: {=VLOOKUP(C14,DB!A:D,3,FALSE)} -> annetandayu553@gmail.com | T14: CARA MEMILIH TANGGAL DENGAN KLIK 2 KALI PADA CELL | U14: =CONCATENATE(C14,D14) -> Adriana TandajuJanuari | V14: =IF(M14="",_xludf.SWITCH(D14,"Januari",EOMONTH("01/01/2024",0),"Februari",EOMONTH("01/01/2024",1),"Maret",EOMONTH("01/01/2024",2),"April",EOMONTH("01/01/2024",3),"Mei",EOMONTH("01/01/2024",4),"Juni",EOMONTH("01/01/2024",5),"Juli",EOMONTH("01/01/2024",6),"Agustus",EOMONTH("01/01/2024",7),"September",EOMONTH("01/01/2024",8),"Oktober",EOMONTH("01/01/2024",9),"November",EOMONTH("01/01/2024",10),"Desember",EOMONTH("01/01/2024",11)),M14) -> 45678 | X14: =VLOOKUP(CONCATENATE(C14,D14),'Honor 2025'!A:D,4,FALSE) -> 1949000
A15: =U15&"-"&COUNTIF(U$2:U15,U15) -> Adriana TandajuJanuari-2 | B15: =CONCATENATE(F15,D15,E15) -> Vini Cristin, S.Tr.Stat.JanuariSurvei Harga Konsumen (HK 1.2 Pasar) | C15: Adriana Tandaju | D15: Januari | E15: Survei Harga Konsumen (HK 1.2 Pasar) | F15: Vini Cristin, S.Tr.Stat. | G15: =H15*J15 -> 106000 | H15: 53000 | I15: Dok | J15: 2 | K15: 2903.QMA.006.005.A.521213 | L15: 45665 | M15: 45680 | N15: =_xludf.IFNA(IF(X15>3530000,3530000-X15,""),"") -> #NAME? | R15: {=VLOOKUP(C15,DB!A:D,2,FALSE)} -> JL.PRAMUKA NO.29 | S15: {=VLOOKUP(C15,DB!A:D,3,FALSE)} -> annetandayu553@gmail.com | T15: CARA MEMILIH TANGGAL DENGAN KLIK 2 KALI PADA CELL | U15: =CONCATENATE(C15,D15) -> Adriana TandajuJanuari | V15: =IF(M15="",_xludf.SWITCH(D15,"Januari",EOMONTH("01/01/2024",0),"Februari",EOMONTH("01/01/2024",1),"Maret",EOMONTH("01/01/2024",2),"April",EOMONTH("01/01/2024",3),"Mei",EOMONTH("01/01/2024",4),"Juni",EOMONTH("01/01/2024",5),"Juli",EOMONTH("01/01/2024",6),"Agustus",EOMONTH("01/01/2024",7),"September",EOMONTH("01/01/2024",8),"Oktober",EOMONTH("01/01/2024",9),"November",EOMONTH("01/01/2024",10),"Desember",EOMONTH("01/01/2024",11)),M15) -> 45680 | X15: =VLOOKUP(CONCATENATE(C15,D15),'Honor 2025'!A:D,4,FALSE) -> 1949000
A16: =U16&"-"&COUNTIF(U$2:U16,U16) -> Adriana TandajuJanuari-3 | B16: =CONCATENATE(F16,D16,E16) -> Vini Cristin, S.Tr.Stat.JanuariSurvei Harga Konsumen (HK 2.1 Pasar) | C16: Adriana Tandaju | D16: Januari | E16: Survei Harga Konsumen (HK 2.1 Pasar) | F16: Vini Cristin, S.Tr.Stat. | G16: =H16*J16 -> 86000 | H16: 86000 | I16: Dok | J16: 1 | K16: 2903.QMA.006.005.A.521213 | L16: 45671 | M16: 45673 | N16: =_xludf.IFNA(IF(X16>3530000,3530000-X16,""),"") -> #NAME? | R16: {=VLOOKUP(C16,DB!A:D,2,FALSE)} -> JL.PRAMUKA NO.29 | S16: {=VLOOKUP(C16,DB!A:D,3,FALSE)} -> annetandayu553@gmail.com | T16: CARA MEMILIH TANGGAL DENGAN KLIK 2 KALI PADA CELL | U16: =CONCATENATE(C16,D16) -> Adriana TandajuJanuari | V16: =IF(M16="",_xludf.SWITCH(D16,"Januari",EOMONTH("01/01/2024",0),"Februari",EOMONTH("01/01/2024",1),"Maret",EOMONTH("01/01/2024",2),"April",EOMONTH("01/01/2024",3),"Mei",EOMONTH("01/01/2024",4),"Juni",EOMONTH("01/01/2024",5),"Juli",EOMONTH("01/01/2024",6),"Agustus",EOMONTH("01/01/2024",7),"September",EOMONTH("01/01/2024",8),"Oktober",EOMONTH("01/01/2024",9),"November",EOMONTH("01/01/2024",10),"Desember",EOMONTH("01/01/2024",11)),M16) -> 45673 | X16: =VLOOKUP(CONCATENATE(C16,D16),'Honor 2025'!A:D,4,FALSE) -> 1949000
A17: =U17&"-"&COUNTIF(U$2:U17,U17) -> Adriana TandajuJanuari-4 | B17: =CONCATENATE(F17,D17,E17) -> Vini Cristin, S.Tr.Stat.JanuariSurvei Harga Konsumen (HK 2.2 Pasar) | C17: Adriana Tandaju | D17: Januari | E17: Survei Harga Konsumen (HK 2.2 Pasar) | F17: Vini Cristin, S.Tr.Stat. | G17: =H17*J17 -> 92000 | H17: 92000 | I17: Dok | J17: 1 | K17: 2903.QMA.006.005.A.521213 | L17: 45662 | M17: 45672 | N17: =_xludf.IFNA(IF(X17>3530000,3530000-X17,""),"") -> #NAME? | R17: {=VLOOKUP(C17,DB!A:D,2,FALSE)} -> JL.PRAMUKA NO.29 | S17: {=VLOOKUP(C17,DB!A:D,3,FALSE)} -> annetandayu553@gmail.com | T17: CARA MEMILIH TANGGAL DENGAN KLIK 2 KALI PADA CELL | U17: =CONCATENATE(C17,D17) -> Adriana TandajuJanuari | V17: =IF(M17="",_xludf.SWITCH(D17,"Januari",EOMONTH("01/01/2024",0),"Februari",EOMONTH("01/01/2024",1),"Maret",EOMONTH("01/01/2024",2),"April",EOMONTH("01/01/2024",3),"Mei",EOMONTH("01/01/2024",4),"Juni",EOMONTH("01/01/2024",5),"Juli",EOMONTH("01/01/2024",6),"Agustus",EOMONTH("01/01/2024",7),"September",EOMONTH("01/01/2024",8),"Oktober",EOMONTH("01/01/2024",9),"November",EOMONTH("01/01/2024",10),"Desember",EOMONTH("01/01/2024",11)),M17) -> 45672 | X17: =VLOOKUP(CONCATENATE(C17,D17),'Honor 2025'!A:D,4,FALSE) -> 1949000
A18: =U18&"-"&COUNTIF(U$2:U18,U18) -> Adriana TandajuJanuari-5 | B18: =CONCATENATE(F18,D18,E18) -> Vini Cristin, S.Tr.Stat.JanuariSurvei Harga Konsumen (HK 4, 5, 6) | C18: Adriana Tandaju | D18: Januari | E18: Survei Harga Konsumen (HK 4, 5, 6) | F18: Vini Cristin, S.Tr.Stat. | G18: =H18*J18 -> 672000 | H18: 48000 | I18: Dok | J18: 14 | K18: 2903.QMA.006.005.A.521213 | L18: 45659 | M18: 45667 | N18: =_xludf.IFNA(IF(X18>3530000,3530000-X18,""),"") -> #NAME? | R18: {=VLOOKUP(C18,DB!A:D,2,FALSE)} -> JL.PRAMUKA NO.29 | S18: {=VLOOKUP(C18,DB!A:D,3,FALSE)} -> annetandayu553@gmail.com | T18: CARA MEMILIH TANGGAL DENGAN KLIK 2 KALI PADA CELL | U18: =CONCATENATE(C18,D18) -> Adriana TandajuJanuari | V18: =IF(M18="",_xludf.SWITCH(D18,"Januari",EOMONTH("01/01/2024",0),"Februari",EOMONTH("01/01/2024",1),"Maret",EOMONTH("01/01/2024",2),"April",EOMONTH("01/01/2024",3),"Mei",EOMONTH("01/01/2024",4),"Juni",EOMONTH("01/01/2024",5),"Juli",EOMONTH("01/01/2024",6),"Agustus",EOMONTH("01/01/2024",7),"September",EOMONTH("01/01/2024",8),"Oktober",EOMONTH("01/01/2024",9),"November",EOMONTH("01/01/2024",10),"Desember",EOMONTH("01/01/2024",11)),M18) -> 45667 | X18: =VLOOKUP(CONCATENATE(C18,D18),'Honor 2025'!A:D,4,FALSE) -> 1949000
A19: =U19&"-"&COUNTIF(U$2:U19,U19) -> Stephen christiani kenteyJanuari-1 | B19: =CONCATENATE(F19,D19,E19) -> Vini Cristin, S.Tr.Stat.JanuariSurvei Harga Konsumen (HK 1.1 Pasar) | C19: Stephen christiani kentey | D19: Januari | E19: Survei Harga Konsumen (HK 1.1 Pasar) | F19: Vini Cristin, S.Tr.Stat. | G19: =H19*J19 -> 225000 | H19: 45000 | I19: Dok | J19: 5 | K19: 2903.QMA.006.005.A.521213 | L19: 45663 | M19: 45678 | N19: =_xludf.IFNA(IF(X19>3530000,3530000-X19,""),"") -> #NAME? | R19: {=VLOOKUP(C19,DB!A:D,2,FALSE)} -> Ranotana weru lingkungan 5 | S19: {=VLOOKUP(C19,DB!A:D,3,FALSE)} -> Stephenkentey@gmail.com | T19: CARA MEMILIH TANGGAL DENGAN KLIK 2 KALI PADA CELL | U19: =CONCATENATE(C19,D19) -> Stephen christiani kenteyJanuari | V19: =IF(M19="",_xludf.SWITCH(D19,"Januari",EOMONTH("01/01/2024",0),"Februari",EOMONTH("01/01/2024",1),"Maret",EOMONTH("01/01/2024",2),"April",EOMONTH("01/01/2024",3),"Mei",EOMONTH("01/01/2024",4),"Juni",EOMONTH("01/01/2024",5),"Juli",EOMONTH("01/01/2024",6),"Agustus",EOMONTH("01/01/2024",7),"September",EOMONTH("01/01/2024",8),"Oktober",EOMONTH("01/01/2024",9),"November",EOMONTH("01/01/2024",10),"Desember",EOMONTH("01/01/2024",11)),M19) -> 45678 | X19: =VLOOKUP(CONCATENATE(C19,D19),'Honor 2025'!A:D,4,FALSE) -> 1329000
A20: =U20&"-"&COUNTIF(U$2:U20,U20) -> Stephen christiani kenteyJanuari-2 | B20: =CONCATENATE(F20,D20,E20) -> Vini Cristin, S.Tr.Stat.JanuariSurvei Harga Konsumen (HK 1.2 Pasar) | C20: Stephen christiani kentey | D20: Januari | E20: Survei Harga Konsumen (HK 1.2 Pasar) | F20: Vini Cristin, S.Tr.Stat. | G20: =H20*J20 -> 106000 | H20: 53000 | I20: Dok | J20: 2 | K20: 2903.QMA.006.005.A.521213 | L20: 45665 | M20: 45680 | N20: =_xludf.IFNA(IF(X20>3530000,3530000-X20,""),"") -> #NAME? | R20: {=VLOOKUP(C20,DB!A:D,2,FALSE)} -> Ranotana weru lingkungan 5 | S20: {=VLOOKUP(C20,DB!A:D,3,FALSE)} -> Stephenkentey@gmail.com | T20: CARA MEMILIH TANGGAL DENGAN KLIK 2 KALI PADA CELL | U20: =CONCATENATE(C20,D20) -> Stephen christiani kenteyJanuari | V20: =IF(M20="",_xludf.SWITCH(D20,"Januari",EOMONTH("01/01/2024",0),"Februari",EOMONTH("01/01/2024",1),"Maret",EOMONTH("01/01/2024",2),"April",EOMONTH("01/01/2024",3),"Mei",EOMONTH("01/01/2024",4),"Juni",EOMONTH("01/01/2024",5),"Juli",EOMONTH("01/01/2024",6),"Agustus",EOMONTH("01/01/2024",7),"September",EOMONTH("01/01/2024",8),"Oktober",EOMONTH("01/01/2024",9),"November",EOMONTH("01/01/2024",10),"Desember",EOMONTH("01/01/2024",11)),M20) -> 45680 | X20: =VLOOKUP(CONCATENATE(C20,D20),'Honor 2025'!A:D,4,FALSE) -> 1329000
A21: =U21&"-"&COUNTIF(U$2:U21,U21) -> Stephen christiani kenteyJanuari-3 | B21: =CONCATENATE(F21,D21,E21) -> Vini Cristin, S.Tr.Stat.JanuariSurvei Harga Konsumen (HK 2.1 Pasar) | C21: Stephen christiani kentey | D21: Januari | E21: Survei Harga Konsumen (HK 2.1 Pasar) | F21: Vini Cristin, S.Tr.Stat. | G21: =H21*J21 -> 86000 | H21: 86000 | I21: Dok | J21: 1 | K21: 2903.QMA.006.005.A.521213 | L21: 45671 | M21: 45673 | N21: =_xludf.IFNA(IF(X21>3530000,3530000-X21,""),"") -> #NAME? | R21: {=VLOOKUP(C21,DB!A:D,2,FALSE)} -> Ranotana weru lingkungan 5 | S21: {=VLOOKUP(C21,DB!A:D,3,FALSE)} -> Stephenkentey@gmail.com | T21: CARA MEMILIH TANGGAL DENGAN KLIK 2 KALI PADA CELL | U21: =CONCATENATE(C21,D21) -> Stephen christiani kenteyJanuari | V21: =IF(M21="",_xludf.SWITCH(D21,"Januari",EOMONTH("01/01/2024",0),"Februari",EOMONTH("01/01/2024",1),"Maret",EOMONTH("01/01/2024",2),"April",EOMONTH("01/01/2024",3),"Mei",EOMONTH("01/01/2024",4),"Juni",EOMONTH("01/01/2024",5),"Juli",EOMONTH("01/01/2024",6),"Agustus",EOMONTH("01/01/2024",7),"September",EOMONTH("01/01/2024",8),"Oktober",EOMONTH("01/01/2024",9),"November",EOMONTH("01/01/2024",10),"Desember",EOMONTH("01/01/2024",11)),M21) -> 45673 | X21: =VLOOKUP(CONCATENATE(C21,D21),'Honor 2025'!A:D,4,FALSE) -> 1329000
A22: =U22&"-"&COUNTIF(U$2:U22,U22) -> Stephen christiani kenteyJanuari-4 | B22: =CONCATENATE(F22,D22,E22) -> Vini Cristin, S.Tr.Stat.JanuariSurvei Harga Konsumen (HK 4, 5, 6) | C22: Stephen christiani kentey | D22: Januari | E22: Survei Harga Konsumen (HK 4, 5, 6) | F22: Vini Cristin, S.Tr.Stat. | G22: =H22*J22 -> 672000 | H22: 48000 | I22: Dok | J22: 14 | K22: 2903.QMA.006.005.A.521213 | L22: 45659 | M22: 45667 | N22: =_xludf.IFNA(IF(X22>3530000,3530000-X22,""),"") -> #NAME? | R22: {=VLOOKUP(C22,DB!A:D,2,FALSE)} -> Ranotana weru lingkungan 5 | S22: {=VLOOKUP(C22,DB!A:D,3,FALSE)} -> Stephenkentey@gmail.com | T22: CARA MEMILIH TANGGAL DENGAN KLIK 2 KALI PADA CELL | U22: =CONCATENATE(C22,D22) -> Stephen christiani kenteyJanuari | V22: =IF(M22="",_xludf.SWITCH(D22,"Januari",EOMONTH("01/01/2024",0),"Februari",EOMONTH("01/01/2024",1),"Maret",EOMONTH("01/01/2024",2),"April",EOMONTH("01/01/2024",3),"Mei",EOMONTH("01/01/2024",4),"Juni",EOMONTH("01/01/2024",5),"Juli",EOMONTH("01/01/2024",6),"Agustus",EOMONTH("01/01/2024",7),"September",EOMONTH("01/01/2024",8),"Oktober",EOMONTH("01/01/2024",9),"November",EOMONTH("01/01/2024",10),"Desember",EOMONTH("01/01/2024",11)),M22) -> 45667 | X22: =VLOOKUP(CONCATENATE(C22,D22),'Honor 2025'!A:D,4,FALSE) -> 1329000
A23: =U23&"-"&COUNTIF(U$2:U23,U23) -> Roy MakalewJanuari-1 | B23: =CONCATENATE(F23,D23,E23) -> Vini Cristin, S.Tr.Stat.JanuariSurvei Harga Konsumen (HK 1.1 Pasar) | C23: Roy Makalew | D23: Januari | E23: Survei Harga Konsumen (HK 1.1 Pasar) | F23: Vini Cristin, S.Tr.Stat. | G23: =H23*J23 -> 225000 | H23: 45000 | I23: Dok | J23: 5 | K23: 2903.QMA.006.005.A.521213 | L23: 45663 | M23: 45678 | N23: =_xludf.IFNA(IF(X23>3530000,3530000-X23,""),"") -> #NAME? | R23: {=VLOOKUP(C23,DB!A:D,2,FALSE)} -> Jalan Kleak 77, no 58 | S23: {=VLOOKUP(C23,DB!A:D,3,FALSE)} -> roymakalew2511@gmail.com | T23: CARA MEMILIH TANGGAL DENGAN KLIK 2 KALI PADA CELL | U23: =CONCATENATE(C23,D23) -> Roy MakalewJanuari | V23: =IF(M23="",_xludf.SWITCH(D23,"Januari",EOMONTH("01/01/2024",0),"Februari",EOMONTH("01/01/2024",1),"Maret",EOMONTH("01/01/2024",2),"April",EOMONTH("01/01/2024",3),"Mei",EOMONTH("01/01/2024",4),"Juni",EOMONTH("01/01/2024",5),"Juli",EOMONTH("01/01/2024",6),"Agustus",EOMONTH("01/01/2024",7),"September",EOMONTH("01/01/2024",8),"Oktober",EOMONTH("01/01/2024",9),"November",EOMONTH("01/01/2024",10),"Desember",EOMONTH("01/01/2024",11)),M23) -> 45678 | X23: =VLOOKUP(CONCATENATE(C23,D23),'Honor 2025'!A:D,4,FALSE) -> 1392000
A24: =U24&"-"&COUNTIF(U$2:U24,U24) -> Roy MakalewJanuari-2 | B24: =CONCATENATE(F24,D24,E24) -> Vini Cristin, S.Tr.Stat.JanuariSurvei Harga Konsumen (HK 1.2 Pasar) | C24: Roy Makalew | D24: Januari | E24: Survei Harga Konsumen (HK 1.2 Pasar) | F24: Vini Cristin, S.Tr.Stat. | G24: =H24*J24 -> 106000 | H24: 53000 | I24: Dok | J24: 2 | K24: 2903.QMA.006.005.A.521213 | L24: 45665 | M24: 45680 | N24: =_xludf.IFNA(IF(X24>3530000,3530000-X24,""),"") -> #NAME? | R24: {=VLOOKUP(C24,DB!A:D,2,FALSE)} -> Jalan Kleak 77, no 58 | S24: {=VLOOKUP(C24,DB!A:D,3,FALSE)} -> roymakalew2511@gmail.com | T24: CARA MEMILIH TANGGAL DENGAN KLIK 2 KALI PADA CELL | U24: =CONCATENATE(C24,D24) -> Roy MakalewJanuari | V24: =IF(M24="",_xludf.SWITCH(D24,"Januari",EOMONTH("01/01/2024",0),"Februari",EOMONTH("01/01/2024",1),"Maret",EOMONTH("01/01/2024",2),"April",EOMONTH("01/01/2024",3),"Mei",EOMONTH("01/01/2024",4),"Juni",EOMONTH("01/01/2024",5),"Juli",EOMONTH("01/01/2024",6),"Agustus",EOMONTH("01/01/2024",7),"September",EOMONTH("01/01/2024",8),"Oktober",EOMONTH("01/01/2024",9),"November",EOMONTH("01/01/2024",10),"Desember",EOMONTH("01/01/2024",11)),M24) -> 45680 | X24: =VLOOKUP(CONCATENATE(C24,D24),'Honor 2025'!A:D,4,FALSE) -> 1392000
A25: =U25&"-"&COUNTIF(U$2:U25,U25) -> Roy MakalewJanuari-3 | B25: =CONCATENATE(F25,D25,E25) -> Vini Cristin, S.Tr.Stat.JanuariSurvei Harga Konsumen (HK 2.2 Pasar) | C25: Roy Makalew | D25: Januari | E25: Survei Harga Konsumen (HK 2.2 Pasar) | F25: Vini Cristin, S.Tr.Stat. | G25: =H25*J25 -> 92000 | H25: 92000 | I25: Dok | J25: 1 | K25: 2903.QMA.006.005.A.521213 | L25: 45662 | M25: 45672 | N25: =_xludf.IFNA(IF(X25>3530000,3530000-X25,""),"") -> #NAME? | R25: {=VLOOKUP(C25,DB!A:D,2,FALSE)} -> Jalan Kleak 77, no 58 | S25: {=VLOOKUP(C25,DB!A:D,3,FALSE)} -> roymakalew2511@gmail.com | T25: CARA MEMILIH TANGGAL DENGAN KLIK 2 KALI PADA CELL | U25: =CONCATENATE(C25,D25) -> Roy MakalewJanuari | V25: =IF(M25="",_xludf.SWITCH(D25,"Januari",EOMONTH("01/01/2024",0),"Februari",EOMONTH("01/01/2024",1),"Maret",EOMONTH("01/01/2024",2),"April",EOMONTH("01/01/2024",3),"Mei",EOMONTH("01/01/2024",4),"Juni",EOMONTH("01/01/2024",5),"Juli",EOMONTH("01/01/2024",6),"Agustus",EOMONTH("01/01/2024",7),"September",EOMONTH("01/01/2024",8),"Oktober",EOMONTH("01/01/2024",9),"November",EOMONTH("01/01/2024",10),"Desember",EOMONTH("01/01/2024",11)),M25) -> 45672 | X25: =VLOOKUP(CONCATENATE(C25,D25),'Honor 2025'!A:D,4,FALSE) -> 1392000
... A91: =U91&"-"&COUNTIF(U$2:U91,U91) -> JOVELIE E WOKASJanuari-4 | B91: =CONCATENATE(F91,D91,E91) -> Fadila Ahmad, S.Tr.Stat.JanuariSurvei Harga Perdagangan Besar Bulanan | C91: JOVELIE E WOKAS | D91: Januari | E91: Survei Harga Perdagangan Besar Bulanan | F91: Fadila Ahmad, S.Tr.Stat. | G91: =H91*J91 -> 192000 | H91: 48000 | I91: Dok | J91: 4 | K91: 2903.BMA.009.005.A.521213 | L91: 45659 | M91: 45677 | N91: =_xludf.IFNA(IF(X91>3530000,3530000-X91,""),"") -> #NAME? | R91: {=VLOOKUP(C91,DB!A:D,2,FALSE)} -> Malalayang Satu Lingkungan 6 | S91: {=VLOOKUP(C91,DB!A:D,3,FALSE)} -> vhellywokas07@gmail.com | T91: CARA MEMILIH TANGGAL DENGAN KLIK 2 KALI PADA CELL | U91: =CONCATENATE(C91,D91) -> JOVELIE E WOKASJanuari | V91: =IF(M91="",_xludf.SWITCH(D91,"Januari",EOMONTH("01/01/2024",0),"Februari",EOMONTH("01/01/2024",1),"Maret",EOMONTH("01/01/2024",2),"April",EOMONTH("01/01/2024",3),"Mei",EOMONTH("01/01/2024",4),"Juni",EOMONTH("01/01/2024",5),"Juli",EOMONTH("01/01/2024",6),"Agustus",EOMONTH("01/01/2024",7),"September",EOMONTH("01/01/2024",8),"Oktober",EOMONTH("01/01/2024",9),"November",EOMONTH("01/01/2024",10),"Desember",EOMONTH("01/01/2024",11)),M91) -> 45677 | X91: =VLOOKUP(CONCATENATE(C91,D91),'Honor 2025'!A:D,4,FALSE) -> 1530000
A92: =U92&"-"&COUNTIF(U$2:U92,U92) -> Farida TampangJanuari-5 | B92: =CONCATENATE(F92,D92,E92) -> Fadila Ahmad, S.Tr.Stat.JanuariSurvei Harga Perdagangan Besar Dwimingguan | C92: Farida Tampang | D92: Januari | E92: Survei Harga Perdagangan Besar Dwimingguan | F92: Fadila Ahmad, S.Tr.Stat. | G92: =H92*J92 -> 336000 | H92: 48000 | I92: Dok | J92: 7 | K92: #N/A | L92: 45659 | M92: 45677 | N92: =_xludf.IFNA(IF(X92>3530000,3530000-X92,""),"") -> #NAME? | R92: {=VLOOKUP(C92,DB!A:D,2,FALSE)} -> Perum Malalayang Permai Blok B Lingkungan 5 | S92: {=VLOOKUP(C92,DB!A:D,3,FALSE)} -> frydatampang30730@gmail.com | T92: CARA MEMILIH TANGGAL DENGAN KLIK 2 KALI PADA CELL | U92: =CONCATENATE(C92,D92) -> Farida TampangJanuari | V92: =IF(M92="",_xludf.SWITCH(D92,"Januari",EOMONTH("01/01/2024",0),"Februari",EOMONTH("01/01/2024",1),"Maret",EOMONTH("01/01/2024",2),"April",EOMONTH("01/01/2024",3),"Mei",EOMONTH("01/01/2024",4),"Juni",EOMONTH("01/01/2024",5),"Juli",EOMONTH("01/01/2024",6),"Agustus",EOMONTH("01/01/2024",7),"September",EOMONTH("01/01/2024",8),"Oktober",EOMONTH("01/01/2024",9),"November",EOMONTH("01/01/2024",10),"Desember",EOMONTH("01/01/2024",11)),M92) -> 45677 | X92: =VLOOKUP(CONCATENATE(C92,D92),'Honor 2025'!A:D,4,FALSE) -> 2718000
A93: =U93&"-"&COUNTIF(U$2:U93,U93) -> Reini Clara PaulusJanuari-6 | B93: =CONCATENATE(F93,D93,E93) -> Fadila Ahmad, S.Tr.Stat.JanuariSurvei Harga Perdagangan Besar Dwimingguan | C93: Reini Clara Paulus | D93: Januari | E93: Survei Harga Perdagangan Besar Dwimingguan | F93: Fadila Ahmad, S.Tr.Stat. | G93: =H93*J93 -> 336000 | H93: 48000 | I93: Dok | J93: 7 | K93: #N/A | L93: 45659 | M93: 45677 | N93: =_xludf.IFNA(IF(X93>3530000,3530000-X93,""),"") -> #NAME? | R93: {=VLOOKUP(C93,DB!A:D,2,FALSE)} -> Jalan Teluk Tomini No. 170 | S93: {=VLOOKUP(C93,DB!A:D,3,FALSE)} -> reinizalora@gmail.com | T93: CARA MEMILIH TANGGAL DENGAN KLIK 2 KALI PADA CELL | U93: =CONCATENATE(C93,D93) -> Reini Clara PaulusJanuari | V93: =IF(M93="",_xludf.SWITCH(D93,"Januari",EOMONTH("01/01/2024",0),"Februari",EOMONTH("01/01/2024",1),"Maret",EOMONTH("01/01/2024",2),"April",EOMONTH("01/01/2024",3),"Mei",EOMONTH("01/01/2024",4),"Juni",EOMONTH("01/01/2024",5),"Juli",EOMONTH("01/01/2024",6),"Agustus",EOMONTH("01/01/2024",7),"September",EOMONTH("01/01/2024",8),"Oktober",EOMONTH("01/01/2024",9),"November",EOMONTH("01/01/2024",10),"Desember",EOMONTH("01/01/2024",11)),M93) -> 45677 | X93: =VLOOKUP(CONCATENATE(C93,D93),'Honor 2025'!A:D,4,FALSE) -> 3426000
A94: =U94&"-"&COUNTIF(U$2:U94,U94) -> Rina ArnowoJanuari-5 | B94: =CONCATENATE(F94,D94,E94) -> Fadila Ahmad, S.Tr.Stat.JanuariSurvei Harga Perdagangan Besar Dwimingguan | C94: Rina Arnowo | D94: Januari | E94: Survei Harga Perdagangan Besar Dwimingguan | F94: Fadila Ahmad, S.Tr.Stat. | G94: =H94*J94 -> 480000 | H94: 48000 | I94: Dok | J94: 10 | K94: #N/A | L94: 45659 | M94: 45677 | N94: =_xludf.IFNA(IF(X94>3530000,3530000-X94,""),"") -> #NAME? | R94: {=VLOOKUP(C94,DB!A:D,2,FALSE)} -> Malalayang 1 timur | S94: {=VLOOKUP(C94,DB!A:D,3,FALSE)} -> rinaarnowo26@gmail.com | T94: CARA MEMILIH TANGGAL DENGAN KLIK 2 KALI PADA CELL | U94: =CONCATENATE(C94,D94) -> Rina ArnowoJanuari | V94: =IF(M94="",_xludf.SWITCH(D94,"Januari",EOMONTH("01/01/2024",0),"Februari",EOMONTH("01/01/2024",1),"Maret",EOMONTH("01/01/2024",2),"April",EOMONTH("01/01/2024",3),"Mei",EOMONTH("01/01/2024",4),"Juni",EOMONTH("01/01/2024",5),"Juli",EOMONTH("01/01/2024",6),"Agustus",EOMONTH("01/01/2024",7),"September",EOMONTH("01/01/2024",8),"Oktober",EOMONTH("01/01/2024",9),"November",EOMONTH("01/01/2024",10),"Desember",EOMONTH("01/01/2024",11)),M94) -> 45677 | X94: =VLOOKUP(CONCATENATE(C94,D94),'Honor 2025'!A:D,4,FALSE) -> 1893000
A95: =U95&"-"&COUNTIF(U$2:U95,U95) -> Adriana TandajuJanuari-7 | B95: =CONCATENATE(F95,D95,E95) -> Fadila Ahmad, S.Tr.Stat.JanuariSurvei Harga Perdagangan Besar Dwimingguan | C95: Adriana Tandaju | D95: Januari | E95: Survei Harga Perdagangan Besar Dwimingguan | F95: Fadila Ahmad, S.Tr.Stat. | G95: =H95*J95 -> 576000 | H95: 48000 | I95: Dok | J95: 12 | K95: #N/A | L95: 45659 | M95: 45677 | N95: =_xludf.IFNA(IF(X95>3530000,3530000-X95,""),"") -> #NAME? | R95: {=VLOOKUP(C95,DB!A:D,2,FALSE)} -> JL.PRAMUKA NO.29 | S95: {=VLOOKUP(C95,DB!A:D,3,FALSE)} -> annetandayu553@gmail.com | T95: CARA MEMILIH TANGGAL DENGAN KLIK 2 KALI PADA CELL | U95: =CONCATENATE(C95,D95) -> Adriana TandajuJanuari | V95: =IF(M95="",_xludf.SWITCH(D95,"Januari",EOMONTH("01/01/2024",0),"Februari",EOMONTH("01/01/2024",1),"Maret",EOMONTH("01/01/2024",2),"April",EOMONTH("01/01/2024",3),"Mei",EOMONTH("01/01/2024",4),"Juni",EOMONTH("01/01/2024",5),"Juli",EOMONTH("01/01/2024",6),"Agustus",EOMONTH("01/01/2024",7),"September",EOMONTH("01/01/2024",8),"Oktober",EOMONTH("01/01/2024",9),"November",EOMONTH("01/01/2024",10),"Desember",EOMONTH("01/01/2024",11)),M95) -> 45677 | X95: =VLOOKUP(CONCATENATE(C95,D95),'Honor 2025'!A:D,4,FALSE) -> 1949000
A96: =U96&"-"&COUNTIF(U$2:U96,U96) -> Stephen christiani kenteyJanuari-6 | B96: =CONCATENATE(F96,D96,E96) -> Fadila Ahmad, S.Tr.Stat.JanuariSurvei Harga Perdagangan Besar Dwimingguan | C96: Stephen christiani kentey | D96: Januari | E96: Survei Harga Perdagangan Besar Dwimingguan | F96: Fadila Ahmad, S.Tr.Stat. | G96: =H96*J96 -> 144000 | H96: 48000 | I96: Dok | J96: 3 | K96: #N/A | L96: 45659 | M96: 45677 | N96: =_xludf.IFNA(IF(X96>3530000,3530000-X96,""),"") -> #NAME? | R96: {=VLOOKUP(C96,DB!A:D,2,FALSE)} -> Ranotana weru lingkungan 5 | S96: {=VLOOKUP(C96,DB!A:D,3,FALSE)} -> Stephenkentey@gmail.com | T96: CARA MEMILIH TANGGAL DENGAN KLIK 2 KALI PADA CELL | U96: =CONCATENATE(C96,D96) -> Stephen christiani kenteyJanuari | V96: =IF(M96="",_xludf.SWITCH(D96,"Januari",EOMONTH("01/01/2024",0),"Februari",EOMONTH("01/01/2024",1),"Maret",EOMONTH("01/01/2024",2),"April",EOMONTH("01/01/2024",3),"Mei",EOMONTH("01/01/2024",4),"Juni",EOMONTH("01/01/2024",5),"Juli",EOMONTH("01/01/2024",6),"Agustus",EOMONTH("01/01/2024",7),"September",EOMONTH("01/01/2024",8),"Oktober",EOMONTH("01/01/2024",9),"November",EOMONTH("01/01/2024",10),"Desember",EOMONTH("01/01/2024",11)),M96) -> 45677 | X96: =VLOOKUP(CONCATENATE(C96,D96),'Honor 2025'!A:D,4,FALSE) -> 1329000
A97: =U97&"-"&COUNTIF(U$2:U97,U97) -> Heny RumambiJanuari-8 | B97: =CONCATENATE(F97,D97,E97) -> Fadila Ahmad, S.Tr.Stat.JanuariSurvei Harga Perdagangan Besar Dwimingguan | C97: Heny Rumambi | D97: Januari | E97: Survei Harga Perdagangan Besar Dwimingguan | F97: Fadila Ahmad, S.Tr.Stat. | G97: =H97*J97 -> 96000 | H97: 48000 | I97: Dok | J97: 2 | K97: #N/A | L97: 45659 | M97: 45677 | N97: =_xludf.IFNA(IF(X97>3530000,3530000-X97,""),"") -> #NAME? | R97: {=VLOOKUP(C97,DB!A:D,2,FALSE)} -> Jl. Ringkeng BTN Puskopad blok C No. 49A | S97: {=VLOOKUP(C97,DB!A:D,3,FALSE)} -> henyrumambi@gmail.com | T97: CARA MEMILIH TANGGAL DENGAN KLIK 2 KALI PADA CELL | U97: =CONCATENATE(C97,D97) -> Heny RumambiJanuari | V97: =IF(M97="",_xludf.SWITCH(D97,"Januari",EOMONTH("01/01/2024",0),"Februari",EOMONTH("01/01/2024",1),"Maret",EOMONTH("01/01/2024",2),"April",EOMONTH("01/01/2024",3),"Mei",EOMONTH("01/01/2024",4),"Juni",EOMONTH("01/01/2024",5),"Juli",EOMONTH("01/01/2024",6),"Agustus",EOMONTH("01/01/2024",7),"September",EOMONTH("01/01/2024",8),"Oktober",EOMONTH("01/01/2024",9),"November",EOMONTH("01/01/2024",10),"Desember",EOMONTH("01/01/2024",11)),M97) -> 45677 | X97: =VLOOKUP(CONCATENATE(C97,D97),'Honor 2025'!A:D,4,FALSE) -> 1525000
A98: =U98&"-"&COUNTIF(U$2:U98,U98) -> JOVELIE E WOKASJanuari-5 | B98: =CONCATENATE(F98,D98,E98) -> Fadila Ahmad, S.Tr.Stat.JanuariSurvei Harga Perdagangan Besar Dwimingguan | C98: JOVELIE E WOKAS | D98: Januari | E98: Survei Harga Perdagangan Besar Dwimingguan | F98: Fadila Ahmad, S.Tr.Stat. | G98: =H98*J98 -> 48000 | H98: 48000 | I98: Dok | J98: 1 | K98: #N/A | L98: 45659 | M98: 45677 | N98: =_xludf.IFNA(IF(X98>3530000,3530000-X98,""),"") -> #NAME? | R98: {=VLOOKUP(C98,DB!A:D,2,FALSE)} -> Malalayang Satu Lingkungan 6 | S98: {=VLOOKUP(C98,DB!A:D,3,FALSE)} -> vhellywokas07@gmail.com | T98: CARA MEMILIH TANGGAL DENGAN KLIK 2 KALI PADA CELL | U98: =CONCATENATE(C98,D98) -> JOVELIE E WOKASJanuari | V98: =IF(M98="",_xludf.SWITCH(D98,"Januari",EOMONTH("01/01/2024",0),"Februari",EOMONTH("01/01/2024",1),"Maret",EOMONTH("01/01/2024",2),"April",EOMONTH("01/01/2024",3),"Mei",EOMONTH("01/01/2024",4),"Juni",EOMONTH("01/01/2024",5),"Juli",EOMONTH("01/01/2024",6),"Agustus",EOMONTH("01/01/2024",7),"September",EOMONTH("01/01/2024",8),"Oktober",EOMONTH("01/01/2024",9),"November",EOMONTH("01/01/2024",10),"Desember",EOMONTH("01/01/2024",11)),M98) -> 45677 | X98: =VLOOKUP(CONCATENATE(C98,D98),'Honor 2025'!A:D,4,FALSE) -> 1530000
A99: =U99&"-"&COUNTIF(U$2:U99,U99) -> Roy MakalewJanuari-7 | B99: =CONCATENATE(F99,D99,E99) -> Fadila Ahmad, S.Tr.Stat.JanuariSurvei Harga Perdagangan Besar Dwimingguan | C99: Roy Makalew | D99: Januari | E99: Survei Harga Perdagangan Besar Dwimingguan | F99: Fadila Ahmad, S.Tr.Stat. | G99: =H99*J99 -> 144000 | H99: 48000 | I99: Dok | J99: 3 | K99: #N/A | L99: 45659 | M99: 45677 | N99: =_xludf.IFNA(IF(X99>3530000,3530000-X99,""),"") -> #NAME? | R99: {=VLOOKUP(C99,DB!A:D,2,FALSE)} -> Jalan Kleak 77, no 58 | S99: {=VLOOKUP(C99,DB!A:D,3,FALSE)} -> roymakalew2511@gmail.com | T99: CARA MEMILIH TANGGAL DENGAN KLIK 2 KALI PADA CELL | U99: =CONCATENATE(C99,D99) -> Roy MakalewJanuari | V99: =IF(M99="",_xludf.SWITCH(D99,"Januari",EOMONTH("01/01/2024",0),"Februari",EOMONTH("01/01/2024",1),"Maret",EOMONTH("01/01/2024",2),"April",EOMONTH("01/01/2024",3),"Mei",EOMONTH("01/01/2024",4),"Juni",EOMONTH("01/01/2024",5),"Juli",EOMONTH("01/01/2024",6),"Agustus",EOMONTH("01/01/2024",7),"September",EOMONTH("01/01/2024",8),"Oktober",EOMONTH("01/01/2024",9),"November",EOMONTH("01/01/2024",10),"Desember",EOMONTH("01/01/2024",11)),M99) -> 45677 | X99: =VLOOKUP(CONCATENATE(C99,D99),'Honor 2025'!A:D,4,FALSE) -> 1392000
A100: =U100&"-"&COUNTIF(U$2:U100,U100) -> Sri MulyawatiJanuari-7 | B100: =CONCATENATE(F100,D100,E100) -> Fadila Ahmad, S.Tr.Stat.JanuariSurvei Harga Perdagangan Besar Dwimingguan | C100: Sri Mulyawati | D100: Januari | E100: Survei Harga Perdagangan Besar Dwimingguan | F100: Fadila Ahmad, S.Tr.Stat. | G100: =H100*J100 -> 192000 | H100: 48000 | I100: Dok | J100: 4 | K100: #N/A | L100: 45659 | M100: 45677 | N100: =_xludf.IFNA(IF(X100>3530000,3530000-X100,""),"") -> #NAME? | R100: {=VLOOKUP(C100,DB!A:D,2,FALSE)} -> Jl Wiratama no 4 lingkungan 7 | S100: {=VLOOKUP(C100,DB!A:D,3,FALSE)} -> mulyawatisrie75@gmail.com | T100: CARA MEMILIH TANGGAL DENGAN KLIK 2 KALI PADA CELL | U100: =CONCATENATE(C100,D100) -> Sri MulyawatiJanuari | V100: =IF(M100="",_xludf.SWITCH(D100,"Januari",EOMONTH("01/01/2024",0),"Februari",EOMONTH("01/01/2024",1),"Maret",EOMONTH("01/01/2024",2),"April",EOMONTH("01/01/2024",3),"Mei",EOMONTH("01/01/2024",4),"Juni",EOMONTH("01/01/2024",5),"Juli",EOMONTH("01/01/2024",6),"Agustus",EOMONTH("01/01/2024",7),"September",EOMONTH("01/01/2024",8),"Oktober",EOMONTH("01/01/2024",9),"November",EOMONTH("01/01/2024",10),"Desember",EOMONTH("01/01/2024",11)),M100) -> 45677 | X100: =VLOOKUP(CONCATENATE(C100,D100),'Honor 2025'!A:D,4,FALSE) -> 2357000
A101: =U101&"-"&COUNTIF(U$2:U101,U101) -> Meri adelina kalaloJanuari-1 | B101: =CONCATENATE(F101,D101,E101) -> Kennedy UmadjiJanuariVIMK24 Triwulanan | C101: Meri adelina kalalo | D101: Januari | E101: VIMK24 Triwulanan | F101: Kennedy Umadji | G101: =H101*J101 -> 990000 | H101: 55000 | I101: Dok | J101: 18 | K101: 2904.BMA.006.005.A.524113 | L101: 45659 | M101: 45672 | N101: =_xludf.IFNA(IF(X101>3530000,3530000-X101,""),"") -> #NAME? | R101: {=VLOOKUP(C101,DB!A:D,2,FALSE)} -> Ranotana weru lingkungan 4 | S101: {=VLOOKUP(C101,DB!A:D,3,FALSE)} -> adelinakalalo73@gmail.com | T101: CARA MEMILIH TANGGAL DENGAN KLIK 2 KALI PADA CELL | U101: =CONCATENATE(C101,D101) -> Meri adelina kalaloJanuari | V101: =IF(M101="",_xludf.SWITCH(D101,"Januari",EOMONTH("01/01/2024",0),"Februari",EOMONTH("01/01/2024",1),"Maret",EOMONTH("01/01/2024",2),"April",EOMONTH("01/01/2024",3),"Mei",EOMONTH("01/01/2024",4),"Juni",EOMONTH("01/01/2024",5),"Juli",EOMONTH("01/01/2024",6),"Agustus",EOMONTH("01/01/2024",7),"September",EOMONTH("01/01/2024",8),"Oktober",EOMONTH("01/01/2024",9),"November",EOMONTH("01/01/2024",10),"Desember",EOMONTH("01/01/2024",11)),M101) -> 45672 | X101: =VLOOKUP(CONCATENATE(C101,D101),'Honor 2025'!A:D,4,FALSE) -> 990000
A102: =U102&"-"&COUNTIF(U$2:U102,U102) -> Javey Linda TambayongJanuari-1 | B102: =CONCATENATE(F102,D102,E102) -> Nik'mahJanuariVIMK24 Triwulanan | C102: Javey Linda Tambayong | D102: Januari | E102: VIMK24 Triwulanan | F102: Nik'mah | G102: =H102*J102 -> 605000 | H102: 55000 | I102: Dok | J102: 11 | K102: 2904.BMA.006.005.A.524113 | L102: 45659 | M102: 45672 | N102: =_xludf.IFNA(IF(X102>3530000,3530000-X102,""),"") -> #NAME? | R102: {=VLOOKUP(C102,DB!A:D,2,FALSE)} -> Lingkungan 5 Ranotana Weru Wanea Manado | S102: {=VLOOKUP(C102,DB!A:D,3,FALSE)} -> javeytambayong364@gmail.com | T102: CARA MEMILIH TANGGAL DENGAN KLIK 2 KALI PADA CELL | U102: =CONCATENATE(C102,D102) -> Javey Linda TambayongJanuari | V102: =IF(M102="",_xludf.SWITCH(D102,"Januari",EOMONTH("01/01/2024",0),"Februari",EOMONTH("01/01/2024",1),"Maret",EOMONTH("01/01/2024",2),"April",EOMONTH("01/01/2024",3),"Mei",EOMONTH("01/01/2024",4),"Juni",EOMONTH("01/01/2024",5),"Juli",EOMONTH("01/01/2024",6),"Agustus",EOMONTH("01/01/2024",7),"September",EOMONTH("01/01/2024",8),"Oktober",EOMONTH("01/01/2024",9),"November",EOMONTH("01/01/2024",10),"Desember",EOMONTH("01/01/2024",11)),M102) -> 45672 | X102: =VLOOKUP(CONCATENATE(C102,D102),'Honor 2025'!A:D,4,FALSE) -> 605000
A103: =U103&"-"&COUNTIF(U$2:U103,U103) -> Glendy Queen SupitJanuari-1 | B103: =CONCATENATE(F103,D103,E103) -> Kennedy UmadjiJanuariVIMK24 Triwulanan | C103: Glendy Queen Supit | D103: Januari | E103: VIMK24 Triwulanan | F103: Kennedy Umadji | G103: =H103*J103 -> 1210000 | H103: 55000 | I103: Dok | J103: 22 | K103: 2904.BMA.006.005.A.524113 | L103: 45659 | M103: 45672 | N103: =_xludf.IFNA(IF(X103>3530000,3530000-X103,""),"") -> #NAME? | R103: {=VLOOKUP(C103,DB!A:D,2,FALSE)} -> Bumi Nyiur Lk III | S103: {=VLOOKUP(C103,DB!A:D,3,FALSE)} -> glendyqueen1@gmail.com | T103: CARA MEMILIH TANGGAL DENGAN KLIK 2 KALI PADA CELL | U103: =CONCATENATE(C103,D103) -> Glendy Queen SupitJanuari | V103: =IF(M103="",_xludf.SWITCH(D103,"Januari",EOMONTH("01/01/2024",0),"Februari",EOMONTH("01/01/2024",1),"Maret",EOMONTH("01/01/2024",2),"April",EOMONTH("01/01/2024",3),"Mei",EOMONTH("01/01/2024",4),"Juni",EOMONTH("01/01/2024",5),"Juli",EOMONTH("01/01/2024",6),"Agustus",EOMONTH("01/01/2024",7),"September",EOMONTH("01/01/2024",8),"Oktober",EOMONTH("01/01/2024",9),"November",EOMONTH("01/01/2024",10),"Desember",EOMONTH("01/01/2024",11)),M103) -> 45672 | X103: =VLOOKUP(CONCATENATE(C103,D103),'Honor 2025'!A:D,4,FALSE) -> 1210000
A104: =U104&"-"&COUNTIF(U$2:U104,U104) -> AGUSTINTJE MAKAHANAPJanuari-1 | B104: =CONCATENATE(F104,D104,E104) -> Nik'mahJanuariVIMK24 Triwulanan | C104: AGUSTINTJE MAKAHANAP | D104: Januari | E104: VIMK24 Triwulanan | F104: Nik'mah | G104: =H104*J104 -> 1155000 | H104: 55000 | I104: Dok | J104: 21 | K104: 2904.BMA.006.005.A.524113 | L104: 45659 | M104: 45672 | N104: =_xludf.IFNA(IF(X104>3530000,3530000-X104,""),"") -> #NAME? | R104: {=VLOOKUP(C104,DB!A:D,2,FALSE)} -> Jalan gurita no 8 | S104: {=VLOOKUP(C104,DB!A:D,3,FALSE)} -> Agustintje17@gmail.com | T104: CARA MEMILIH TANGGAL DENGAN KLIK 2 KALI PADA CELL | U104: =CONCATENATE(C104,D104) -> AGUSTINTJE MAKAHANAPJanuari | V104: =IF(M104="",_xludf.SWITCH(D104,"Januari",EOMONTH("01/01/2024",0),"Februari",EOMONTH("01/01/2024",1),"Maret",EOMONTH("01/01/2024",2),"April",EOMONTH("01/01/2024",3),"Mei",EOMONTH("01/01/2024",4),"Juni",EOMONTH("01/01/2024",5),"Juli",EOMONTH("01/01/2024",6),"Agustus",EOMONTH("01/01/2024",7),"September",EOMONTH("01/01/2024",8),"Oktober",EOMONTH("01/01/2024",9),"November",EOMONTH("01/01/2024",10),"Desember",EOMONTH("01/01/2024",11)),M104) -> 45672 | X104: =VLOOKUP(CONCATENATE(C104,D104),'Honor 2025'!A:D,4,FALSE) -> 1155000
A105: =U105&"-"&COUNTIF(U$2:U105,U105) -> STEVI NOVITA WULAN RUMANGKANGJanuari-1 | B105: =CONCATENATE(F105,D105,E105) -> Deyvi Stella Rumangkang, S.E.JanuariSurvei Konstruksi Triwulanan (SKTR) | C105: STEVI NOVITA WULAN RUMANGKANG | D105: Januari | E105: Survei Konstruksi Triwulanan (SKTR) | F105: Deyvi Stella Rumangkang, S.E. | G105: =H105*J105 -> 385000 | H105: 55000 | I105: Dok | J105: 7 | K105: 2904.BMA.006.005.A.521213 | L105: 45659 | M105: 45672 | N105: =_xludf.IFNA(IF(X105>3530000,3530000-X105,""),"") -> #NAME? | R105: {=VLOOKUP(C105,DB!A:D,2,FALSE)} -> Jl Arie Lasut Perum Holly Lestari Blok F10 | S105: {=VLOOKUP(C105,DB!A:D,3,FALSE)} -> stevir89@gmail.com | T105: CARA MEMILIH TANGGAL DENGAN KLIK 2 KALI PADA CELL | U105: =CONCATENATE(C105,D105) -> STEVI NOVITA WULAN RUMANGKANGJanuari | V105: =IF(M105="",_xludf.SWITCH(D105,"Januari",EOMONTH("01/01/2024",0),"Februari",EOMONTH("01/01/2024",1),"Maret",EOMONTH("01/01/2024",2),"April",EOMONTH("01/01/2024",3),"Mei",EOMONTH("01/01/2024",4),"Juni",EOMONTH("01/01/2024",5),"Juli",EOMONTH("01/01/2024",6),"Agustus",EOMONTH("01/01/2024",7),"September",EOMONTH("01/01/2024",8),"Oktober",EOMONTH("01/01/2024",9),"November",EOMONTH("01/01/2024",10),"Desember",EOMONTH("01/01/2024",11)),M105) -> 45672 | X105: =VLOOKUP(CONCATENATE(C105,D105),'Honor 2025'!A:D,4,FALSE) -> 385000
...

Sheet Honor 2025
A1: Helper | B1: Nama | C1: Bulan | D1: Honor | E1: BATAS | F1: TGL TERAKHIR KONTRAK
A2: =CONCATENATE(B2,C2) -> Adhan Yeremia AlhasniJanuari | B2: Adhan Yeremia Alhasni | C2: Januari | D2: =SUMIFS('Data Alokasi Mitra per Bulan'!G:G,'Data Alokasi Mitra per Bulan'!C:C,B2,'Data Alokasi Mitra per Bulan'!D:D,C2) -> 0 | E2: =IF(D2>3530000,"MELEWATI BATAS HONOR","Dibawah Batas Honor") -> Dibawah Batas Honor | F2: =IF(_xludf.MAXifs('Data Alokasi Mitra per Bulan'!V:V,'Data Alokasi Mitra per Bulan'!C:C,B2,'Data Alokasi Mitra per Bulan'!D:D,C2)=0,G2,IF(YEAR(_xludf.MAXifs('Data Alokasi Mitra per Bulan'!V:V,'Data Alokasi Mitra per Bulan'!C:C,B2,'Data Alokasi Mitra per Bulan'!D:D,C2))=2024,G2,_xludf.MAXifs('Data Alokasi Mitra per Bulan'!V:V,'Data Alokasi Mitra per Bulan'!C:C,B2,'Data Alokasi Mitra per Bulan'!D:D,C2))) -> #NAME? | G2: =EOMONTH("1/1/2025",0) -> 45688
A3: =CONCATENATE(B3,C3) -> Adriana TandajuJanuari | B3: Adriana Tandaju | C3: Januari | D3: =SUMIFS('Data Alokasi Mitra per Bulan'!G:G,'Data Alokasi Mitra per Bulan'!C:C,B3,'Data Alokasi Mitra per Bulan'!D:D,C3) -> 1949000 | E3: =IF(D3>3530000,"MELEWATI BATAS HONOR","Dibawah Batas Honor") -> Dibawah Batas Honor | F3: =IF(_xludf.MAXifs('Data Alokasi Mitra per Bulan'!V:V,'Data Alokasi Mitra per Bulan'!C:C,B3,'Data Alokasi Mitra per Bulan'!D:D,C3)=0,G3,IF(YEAR(_xludf.MAXifs('Data Alokasi Mitra per Bulan'!V:V,'Data Alokasi Mitra per Bulan'!C:C,B3,'Data Alokasi Mitra per Bulan'!D:D,C3))=2024,G3,_xludf.MAXifs('Data Alokasi Mitra per Bulan'!V:V,'Data Alokasi Mitra per Bulan'!C:C,B3,'Data Alokasi Mitra per Bulan'!D:D,C3))) -> #NAME? | G3: =EOMONTH("1/1/2025",0) -> 45688
A4: =CONCATENATE(B4,C4) -> AGUSTINTJE MAKAHANAPJanuari | B4: AGUSTINTJE MAKAHANAP | C4: Januari | D4: =SUMIFS('Data Alokasi Mitra per Bulan'!G:G,'Data Alokasi Mitra per Bulan'!C:C,B4,'Data Alokasi Mitra per Bulan'!D:D,C4) -> 1155000 | E4: =IF(D4>3530000,"MELEWATI BATAS HONOR","Dibawah Batas Honor") -> Dibawah Batas Honor | F4: =IF(_xludf.MAXifs('Data Alokasi Mitra per Bulan'!V:V,'Data Alokasi Mitra per Bulan'!C:C,B4,'Data Alokasi Mitra per Bulan'!D:D,C4)=0,G4,IF(YEAR(_xludf.MAXifs('Data Alokasi Mitra per Bulan'!V:V,'Data Alokasi Mitra per Bulan'!C:C,B4,'Data Alokasi Mitra per Bulan'!D:D,C4))=2024,G4,_xludf.MAXifs('Data Alokasi Mitra per Bulan'!V:V,'Data Alokasi Mitra per Bulan'!C:C,B4,'Data Alokasi Mitra per Bulan'!D:D,C4))) -> #NAME? | G4: =EOMONTH("1/1/2025",0) -> 45688
A5: =CONCATENATE(B5,C5) -> Alice lady diana mantiriJanuari | B5: Alice lady diana mantiri | C5: Januari | D5: =SUMIFS('Data Alokasi Mitra per Bulan'!G:G,'Data Alokasi Mitra per Bulan'!C:C,B5,'Data Alokasi Mitra per Bulan'!D:D,C5) -> 0 | E5: =IF(D5>3530000,"MELEWATI BATAS HONOR","Dibawah Batas Honor") -> Dibawah Batas Honor | F5: =IF(_xludf.MAXifs('Data Alokasi Mitra per Bulan'!V:V,'Data Alokasi Mitra per Bulan'!C:C,B5,'Data Alokasi Mitra per Bulan'!D:D,C5)=0,G5,IF(YEAR(_xludf.MAXifs('Data Alokasi Mitra per Bulan'!V:V,'Data Alokasi Mitra per Bulan'!C:C,B5,'Data Alokasi Mitra per Bulan'!D:D,C5))=2024,G5,_xludf.MAXifs('Data Alokasi Mitra per Bulan'!V:V,'Data Alokasi Mitra per Bulan'!C:C,B5,'Data Alokasi Mitra per Bulan'!D:D,C5))) -> #NAME? | G5: =EOMONTH("1/1/2025",0) -> 45688
A6: =CONCATENATE(B6,C6) -> Alvani Bregina NgongoloyJanuari | B6: Alvani Bregina Ngongoloy | C6: Januari | D6: =SUMIFS('Data Alokasi Mitra per Bulan'!G:G,'Data Alokasi Mitra per Bulan'!C:C,B6,'Data Alokasi Mitra per Bulan'!D:D,C6) -> 1458000 | E6: =IF(D6>3530000,"MELEWATI BATAS HONOR","Dibawah Batas Honor") -> Dibawah Batas Honor | F6: =IF(_xludf.MAXifs('Data Alokasi Mitra per Bulan'!V:V,'Data Alokasi Mitra per Bulan'!C:C,B6,'Data Alokasi Mitra per Bulan'!D:D,C6)=0,G6,IF(YEAR(_xludf.MAXifs('Data Alokasi Mitra per Bulan'!V:V,'Data Alokasi Mitra per Bulan'!C:C,B6,'Data Alokasi Mitra per Bulan'!D:D,C6))=2024,G6,_xludf.MAXifs('Data Alokasi Mitra per Bulan'!V:V,'Data Alokasi Mitra per Bulan'!C:C,B6,'Data Alokasi Mitra per Bulan'!D:D,C6))) -> #NAME? | G6: =EOMONTH("1/1/2025",0) -> 45688
A7: =CONCATENATE(B7,C7) -> anastasia rany makanaungJanuari | B7: anastasia rany makanaung | C7: Januari | D7: =SUMIFS('Data Alokasi Mitra per Bulan'!G:G,'Data Alokasi Mitra per Bulan'!C:C,B7,'Data Alokasi Mitra per Bulan'!D:D,C7) -> 0 | E7: =IF(D7>3530000,"MELEWATI BATAS HONOR","Dibawah Batas Honor") -> Dibawah Batas Honor | F7: =IF(_xludf.MAXifs('Data Alokasi Mitra per Bulan'!V:V,'Data Alokasi Mitra per Bulan'!C:C,B7,'Data Alokasi Mitra per Bulan'!D:D,C7)=0,G7,IF(YEAR(_xludf.MAXifs('Data Alokasi Mitra per Bulan'!V:V,'Data Alokasi Mitra per Bulan'!C:C,B7,'Data Alokasi Mitra per Bulan'!D:D,C7))=2024,G7,_xludf.MAXifs('Data Alokasi Mitra per Bulan'!V:V,'Data Alokasi Mitra per Bulan'!C:C,B7,'Data Alokasi Mitra per Bulan'!D:D,C7))) -> #NAME? | G7: =EOMONTH("1/1/2025",0) -> 45688
A8: =CONCATENATE(B8,C8) -> Anatasya MasudaraJanuari | B8: Anatasya Masudara | C8: Januari | D8: =SUMIFS('Data Alokasi Mitra per Bulan'!G:G,'Data Alokasi Mitra per Bulan'!C:C,B8,'Data Alokasi Mitra per Bulan'!D:D,C8) -> 0 | E8: =IF(D8>3530000,"MELEWATI BATAS HONOR","Dibawah Batas Honor") -> Dibawah Batas Honor | F8: =IF(_xludf.MAXifs('Data Alokasi Mitra per Bulan'!V:V,'Data Alokasi Mitra per Bulan'!C:C,B8,'Data Alokasi Mitra per Bulan'!D:D,C8)=0,G8,IF(YEAR(_xludf.MAXifs('Data Alokasi Mitra per Bulan'!V:V,'Data Alokasi Mitra per Bulan'!C:C,B8,'Data Alokasi Mitra per Bulan'!D:D,C8))=2024,G8,_xludf.MAXifs('Data Alokasi Mitra per Bulan'!V:V,'Data Alokasi Mitra per Bulan'!C:C,B8,'Data Alokasi Mitra per Bulan'!D:D,C8))) -> #NAME? | G8: =EOMONTH("1/1/2025",0) -> 45688
A9: =CONCATENATE(B9,C9) -> ANGELIA FRANSISCA SUNDAHJanuari | B9: ANGELIA FRANSISCA SUNDAH | C9: Januari | D9: =SUMIFS('Data Alokasi Mitra per Bulan'!G:G,'Data Alokasi Mitra per Bulan'!C:C,B9,'Data Alokasi Mitra per Bulan'!D:D,C9) -> 0 | E9: =IF(D9>3530000,"MELEWATI BATAS HONOR","Dibawah Batas Honor") -> Dibawah Batas Honor | F9: =IF(_xludf.MAXifs('Data Alokasi Mitra per Bulan'!V:V,'Data Alokasi Mitra per Bulan'!C:C,B9,'Data Alokasi Mitra per Bulan'!D:D,C9)=0,G9,IF(YEAR(_xludf.MAXifs('Data Alokasi Mitra per Bulan'!V:V,'Data Alokasi Mitra per Bulan'!C:C,B9,'Data Alokasi Mitra per Bulan'!D:D,C9))=2024,G9,_xludf.MAXifs('Data Alokasi Mitra per Bulan'!V:V,'Data Alokasi Mitra per Bulan'!C:C,B9,'Data Alokasi Mitra per Bulan'!D:D,C9))) -> #NAME? | G9: =EOMONTH("1/1/2025",0) -> 45688
A10: =CONCATENATE(B10,C10) -> Anita A BolungJanuari | B10: Anita A Bolung | C10: Januari | D10: =SUMIFS('Data Alokasi Mitra per Bulan'!G:G,'Data Alokasi Mitra per Bulan'!C:C,B10,'Data Alokasi Mitra per Bulan'!D:D,C10) -> 0 | E10: =IF(D10>3530000,"MELEWATI BATAS HONOR","Dibawah Batas Honor") -> Dibawah Batas Honor | F10: =IF(_xludf.MAXifs('Data Alokasi Mitra per Bulan'!V:V,'Data Alokasi Mitra per Bulan'!C:C,B10,'Data Alokasi Mitra per Bulan'!D:D,C10)=0,G10,IF(YEAR(_xludf.MAXifs('Data Alokasi Mitra per Bulan'!V:V,'Data Alokasi Mitra per Bulan'!C:C,B10,'Data Alokasi Mitra per Bulan'!D:D,C10))=2024,G10,_xludf.MAXifs('Data Alokasi Mitra per Bulan'!V:V,'Data Alokasi Mitra per Bulan'!C:C,B10,'Data Alokasi Mitra per Bulan'!D:D,C10))) -> #NAME? | G10: =EOMONTH("1/1/2025",0) -> 45688
A11: =CONCATENATE(B11,C11) -> Anita Afrianti SemenJanuari | B11: Anita Afrianti Semen | C11: Januari | D11: =SUMIFS('Data Alokasi Mitra per Bulan'!G:G,'Data Alokasi Mitra per Bulan'!C:C,B11,'Data Alokasi Mitra per Bulan'!D:D,C11) -> 0 | E11: =IF(D11>3530000,"MELEWATI BATAS HONOR","Dibawah Batas Honor") -> Dibawah Batas Honor | F11: =IF(_xludf.MAXifs('Data Alokasi Mitra per Bulan'!V:V,'Data Alokasi Mitra per Bulan'!C:C,B11,'Data Alokasi Mitra per Bulan'!D:D,C11)=0,G11,IF(YEAR(_xludf.MAXifs('Data Alokasi Mitra per Bulan'!V:V,'Data Alokasi Mitra per Bulan'!C:C,B11,'Data Alokasi Mitra per Bulan'!D:D,C11))=2024,G11,_xludf.MAXifs('Data Alokasi Mitra per Bulan'!V:V,'Data Alokasi Mitra per Bulan'!C:C,B11,'Data Alokasi Mitra per Bulan'!D:D,C11))) -> #NAME? | G11: =EOMONTH("1/1/2025",0) -> 45688
A12: =CONCATENATE(B12,C12) -> Arief RohmanJanuari | B12: Arief Rohman | C12: Januari | D12: =SUMIFS('Data Alokasi Mitra per Bulan'!G:G,'Data Alokasi Mitra per Bulan'!C:C,B12,'Data Alokasi Mitra per Bulan'!D:D,C12) -> 0 | E12: =IF(D12>3530000,"MELEWATI BATAS HONOR","Dibawah Batas Honor") -> Dibawah Batas Honor | F12: =IF(_xludf.MAXifs('Data Alokasi Mitra per Bulan'!V:V,'Data Alokasi Mitra per Bulan'!C:C,B12,'Data Alokasi Mitra per Bulan'!D:D,C12)=0,G12,IF(YEAR(_xludf.MAXifs('Data Alokasi Mitra per Bulan'!V:V,'Data Alokasi Mitra per Bulan'!C:C,B12,'Data Alokasi Mitra per Bulan'!D:D,C12))=2024,G12,_xludf.MAXifs('Data Alokasi Mitra per Bulan'!V:V,'Data Alokasi Mitra per Bulan'!C:C,B12,'Data Alokasi Mitra per Bulan'!D:D,C12))) -> #NAME? | G12: =EOMONTH("1/1/2025",0) -> 45688
A13: =CONCATENATE(B13,C13) -> ARTHUR CARLOS BOGARJanuari | B13: ARTHUR CARLOS BOGAR | C13: Januari | D13: =SUMIFS('Data Alokasi Mitra per Bulan'!G:G,'Data Alokasi Mitra per Bulan'!C:C,B13,'Data Alokasi Mitra per Bulan'!D:D,C13) -> 954000 | E13: =IF(D13>3530000,"MELEWATI BATAS HONOR","Dibawah Batas Honor") -> Dibawah Batas Honor | F13: =IF(_xludf.MAXifs('Data Alokasi Mitra per Bulan'!V:V,'Data Alokasi Mitra per Bulan'!C:C,B13,'Data Alokasi Mitra per Bulan'!D:D,C13)=0,G13,IF(YEAR(_xludf.MAXifs('Data Alokasi Mitra per Bulan'!V:V,'Data Alokasi Mitra per Bulan'!C:C,B13,'Data Alokasi Mitra per Bulan'!D:D,C13))=2024,G13,_xludf.MAXifs('Data Alokasi Mitra per Bulan'!V:V,'Data Alokasi Mitra per Bulan'!C:C,B13,'Data Alokasi Mitra per Bulan'!D:D,C13))) -> #NAME? | G13: =EOMONTH("1/1/2025",0) -> 45688
... A133: =CONCATENATE(B133,C133) -> Yunita Rahayu Ekaputri AbdjulJanuari | B133: Yunita Rahayu Ekaputri Abdjul | C133: Januari | D133: =SUMIFS('Data Alokasi Mitra per Bulan'!G:G,'Data Alokasi Mitra per Bulan'!C:C,B133,'Data Alokasi Mitra per Bulan'!D:D,C133) -> 0 | E133: =IF(D133>3530000,"MELEWATI BATAS HONOR","Dibawah Batas Honor") -> Dibawah Batas Honor | F133: =IF(_xludf.MAXifs('Data Alokasi Mitra per Bulan'!V:V,'Data Alokasi Mitra per Bulan'!C:C,B133,'Data Alokasi Mitra per Bulan'!D:D,C133)=0,G133,IF(YEAR(_xludf.MAXifs('Data Alokasi Mitra per Bulan'!V:V,'Data Alokasi Mitra per Bulan'!C:C,B133,'Data Alokasi Mitra per Bulan'!D:D,C133))=2024,G133,_xludf.MAXifs('Data Alokasi Mitra per Bulan'!V:V,'Data Alokasi Mitra per Bulan'!C:C,B133,'Data Alokasi Mitra per Bulan'!D:D,C133))) -> #NAME? | G133: =EOMONTH("1/1/2025",0) -> 45688
A134: =CONCATENATE(B134,C134) -> Adhan Yeremia AlhasniFebruari | B134: Adhan Yeremia Alhasni | C134: Februari | D134: =SUMIFS('Data Alokasi Mitra per Bulan'!G:G,'Data Alokasi Mitra per Bulan'!C:C,B134,'Data Alokasi Mitra per Bulan'!D:D,C134) -> 2310000 | E134: =IF(D134>3530000,"MELEWATI BATAS HONOR","Dibawah Batas Honor") -> Dibawah Batas Honor | F134: =IF(_xludf.MAXifs('Data Alokasi Mitra per Bulan'!V:V,'Data Alokasi Mitra per Bulan'!C:C,B134,'Data Alokasi Mitra per Bulan'!D:D,C134)=0,G134,IF(YEAR(_xludf.MAXifs('Data Alokasi Mitra per Bulan'!V:V,'Data Alokasi Mitra per Bulan'!C:C,B134,'Data Alokasi Mitra per Bulan'!D:D,C134))=2024,G134,_xludf.MAXifs('Data Alokasi Mitra per Bulan'!V:V,'Data Alokasi Mitra per Bulan'!C:C,B134,'Data Alokasi Mitra per Bulan'!D:D,C134))) -> #NAME? | G134: =EOMONTH("1/2/2025",0) -> 45716
A135: =CONCATENATE(B135,C135) -> Adriana TandajuFebruari | B135: Adriana Tandaju | C135: Februari | D135: =SUMIFS('Data Alokasi Mitra per Bulan'!G:G,'Data Alokasi Mitra per Bulan'!C:C,B135,'Data Alokasi Mitra per Bulan'!D:D,C135) -> 1904000 | E135: =IF(D135>3530000,"MELEWATI BATAS HONOR","Dibawah Batas Honor") -> Dibawah Batas Honor | F135: =IF(_xludf.MAXifs('Data Alokasi Mitra per Bulan'!V:V,'Data Alokasi Mitra per Bulan'!C:C,B135,'Data Alokasi Mitra per Bulan'!D:D,C135)=0,G135,IF(YEAR(_xludf.MAXifs('Data Alokasi Mitra per Bulan'!V:V,'Data Alokasi Mitra per Bulan'!C:C,B135,'Data Alokasi Mitra per Bulan'!D:D,C135))=2024,G135,_xludf.MAXifs('Data Alokasi Mitra per Bulan'!V:V,'Data Alokasi Mitra per Bulan'!C:C,B135,'Data Alokasi Mitra per Bulan'!D:D,C135))) -> #NAME? | G135: =EOMONTH("1/2/2025",0) -> 45716
